<?xml version="1.0"?>
<mujoco>
  <default>
    <default class="collision">
      <geom group="1" />
    </default>
    <default class="visual">
      <geom contype="0" conaffinity="0" group="0" />
    </default>

    <default class="wheel">
      <joint axis="0 0 1" damping="30" frictionloss="1" armature="0.1" stiffness="0.02" />
      <velocity gear="3" kv="100" ctrlrange="-6 6" forcerange="-100 100" />
    </default>

    <default class="wheel_collision">
      <!--
            - solref and solimp values tuned for better contact behavior with ground plane to reduce
      bouncingand allowing for stable movement
             - rgba alpha set to 0 to make collision geom invisible
             -->
      <!-- <geom type="capsule" size="3.79399206e-01 0.001" pos="0 0 0" euler="0 0 0" friction="1.0
      0.05 0.001" solref="0.10 0.7" solimp="0.3 0.6 0.001" rgba="1 0 0 1" group="1" /> -->
      <geom friction="1.0 0.05 0.001" group="1" solref="0.10 0.7" solimp="0.3 0.6 0.001" />

    </default>
  </default>
  <worldbody>
    <!-- base + frames -->
    <body name="obotx_frame_legs" pos="0.0 0.0 -1.0e-1" quat="1.0 0.0 0.0 0.0">
      <freejoint />
      <body name="Cylinder.023" pos="-0.80266184  0.00251772  0.38086176"
        quat="0.70529823  0.70529821  0.05054126 -0.05054126">
        <inertial pos="0.0047195106744766235 1.1501362323760986 0.0025174934417009354" mass="1"
          diaginertia="0.001 0.001 0.001" />
        <!-- screws -->
        <geom name="Gummi-big.003_metal.001" mesh="Plane.077_metal.001"
          pos="-0.24997176229953766 1.2891936302185059 0.25522711873054504"
          quat="0.7071066498756409 -0.7071065902709961 -0.0004634579236153513 0.00046345157898031175"
          type="mesh" material="metal.001" />

        <!-- base + columns -->
        <geom class="collision" name="Cylinder.023_Material.016" mesh="Cylinder.002_Material.016"
          pos="0.0047195106744766235 1.1501362323760986 0.0025174934417009354"
          quat="0.7071066498756409 -0.7071065902709961 -0.0004634579236153513 0.00046345157898031175"
          type="mesh" material="Material.016" />
        <geom class="collision" name="Cylinder.023_Material.017" mesh="Cylinder.002_Material.017"
          pos="0.0047195106744766235 1.1501362323760986 0.0025174934417009354"
          quat="0.7071066498756409 -0.7071065902709961 -0.0004634579236153513 0.00046345157898031175"
          type="mesh" material="Material.017" />
        <geom class="collision" name="Cylinder.023_Kontakt.001" mesh="Cylinder.002_Kontakt.001"
          pos="0.0047195106744766235 1.1501362323760986 0.0025174934417009354"
          quat="0.7071066498756409 -0.7071065902709961 -0.0004634579236153513 0.00046345157898031175"
          type="mesh" material="Kontakt.001" />
        <!-- manipulator axis -->
        <geom class="collision" name="Cylinder.024_Material.019" mesh="Cylinder.024_Material.019"
          pos="-0.3574184477329254 0.6288965344429016 0.0025168892461806536"
          quat="0.7071066498756409 -0.7071065902709961 -0.0004634579236153513 0.00046345157898031175"
          type="mesh" material="Material.019" />

        <!-- middle wheel -->
        <body name="Object_4.012" pos="-1.11854587e-08 -1.48436090e-08 -3.12944254e-10"
          quat="0.70529825 0.70529819 0.05054123 0.05054123">
          <inertial pos="0.0024119329173117876 0.002516985172405839 -0.00480766873806715" mass="1"
            diaginertia="0.002 0.002 0.002" />

          <geom class="wheel_collision" name="Object_4.012_Metal.001" mesh="Object_0.004_Metal.001"
            pos="0.0024119329173117876 0.002516985172405839 -0.00480766873806715"
            quat="9.043271160744183e-17 -0.9974889159202576 -2.4241473273178826e-09 -0.07082231342792511"
            type="mesh" material="Metal.001" />
          <geom class="wheel_collision" name="Object_4.012_Wheel_Metal_Dark.001"
            mesh="Object_0.004_Wheel_Metal_Dark.001"
            pos="0.0024119329173117876 0.002516985172405839 -0.00480766873806715"
            quat="9.043271160744183e-17 -0.9974889159202576 -2.4241473273178826e-09 -0.07082231342792511"
            type="mesh" material="Wheel_Metal_Dark.001" />
          <geom class="wheel_collision" name="Object_4.012_Hub_Plastic.001"
            mesh="Object_0.004_Hub_Plastic.001"
            pos="0.0024119329173117876 0.002516985172405839 -0.00480766873806715"
            quat="9.043271160744183e-17 -0.9974889159202576 -2.4241473273178826e-09 -0.07082231342792511"
            type="mesh" material="Hub_Plastic.001" />
          <geom class="wheel_collision" name="Object_4.012_Rollers.001"
            mesh="Object_0.004_Rollers.001"
            pos="0.0024119329173117876 0.002516985172405839 -0.00480766873806715"
            quat="9.043271160744183e-17 -0.9974889159202576 -2.4241473273178826e-09 -0.07082231342792511"
            type="mesh" material="Rollers.001" />
          <geom class="wheel_collision" name="Object_4.012_Wheel_Metal.001"
            mesh="Object_0.004_Wheel_Metal.001"
            pos="0.0024119329173117876 0.002516985172405839 -0.00480766873806715"
            quat="9.043271160744183e-17 -0.9974889159202576 -2.4241473273178826e-09 -0.07082231342792511"
            type="mesh" material="Wheel_Metal.001" />
          <!-- <geom class="wheel_collision"/> -->
          <joint class="wheel" name="middle_wheel" type="hinge" axis="0 1 0" />
        </body>

        <!-- left legs -->
        <body name="Cylinder.029" pos="0.01267889 3.32641149 0.5750432"
          quat="2.96883639e-01  1.31898984e-07  4.10075279e-08 -9.54913664e-01">
          <inertial pos="-3.5032078926633403e-07 -1.974532466419987e-07 -0.04065989330410957"
            mass="1" diaginertia="0.002 0.002 0.002" />

          <geom class="collision" name="Cylinder.029_Material.016" mesh="Cylinder.029_Material.016"
            pos="-3.5032078926633403e-07 -1.974532466419987e-07 -0.04065989330410957"
            quat="0.16112887859344482 -0.16112904250621796 -0.6885038018226624 0.6885037422180176"
            type="mesh" material="Material.016" />
          <geom class="collision" name="Cylinder.029_Material.017" mesh="Cylinder.029_Material.017"
            pos="-3.5032078926633403e-07 -1.974532466419987e-07 -0.04065989330410957"
            quat="0.16112887859344482 -0.16112904250621796 -0.6885038018226624 0.6885037422180176"
            type="mesh" material="Material.017" />
          <geom class="collision" name="Cylinder.029_Kontakt.001" mesh="Cylinder.029_Kontakt.001"
            pos="-3.5032078926633403e-07 -1.974532466419987e-07 -0.04065989330410957"
            quat="0.16112887859344482 -0.16112904250621796 -0.6885038018226624 0.6885037422180176"
            type="mesh" material="Kontakt.001" />
          <joint name="l_leg_hinge1" type="hinge" axis="0 0 -1" armature="0.1" damping="0.2" />

          <body name="Cylinder.031" pos="6.43282756e-03 3.04027766e-01 1.55640419e-06"
            quat="0.00140157 -0.00861364 -0.99061493 -0.13640348">
            <inertial pos="-0.0010879174806177616 0.5267866849899292 -0.0003037049900740385"
              mass="1" diaginertia="0.002 0.002 0.002" />

            <geom class="collision" name="Cylinder.031_Material.016"
              mesh="Cylinder.031_Material.016"
              pos="-0.0010879174806177616 0.5267866849899292 -0.0003037049900740385"
              quat="0.5897416472434998 0.7771185040473938 0.1307428479194641 0.1766297072172165"
              type="mesh" material="Material.016" />
            <geom class="collision" name="Cylinder.031_Material.017"
              mesh="Cylinder.031_Material.017"
              pos="-0.0010879174806177616 0.5267866849899292 -0.0003037049900740385"
              quat="0.5897416472434998 0.7771185040473938 0.1307428479194641 0.1766297072172165"
              type="mesh" material="Material.017" />
            <joint name="l_leg_hinge2" type="hinge" axis="1 0 0" armature="0.1" damping="0.2" />

            <body name="Cylinder.033" pos="1.73654226e-07 3.08583103 3.76093992e-08"
              quat="-9.45824321e-09  9.99985822e-01  1.12601586e-08  5.32509001e-03">
              <inertial pos="1.1087395250797272e-05 0.6922926902770996 0.006093725562095642"
                mass="1" diaginertia="0.002 0.002 0.002" />

              <geom class="collision" name="Cylinder.033_Material.018"
                mesh="Cylinder.033_Material.018"
                pos="1.1087395250797272e-05 0.6922926902770996 0.006093725562095642"
                quat="0.778048038482666 -0.5890370607376099 0.17248913645744324 -0.13388116657733917"
                type="mesh" material="Material.018" />

              <geom class="collision" name="Circle.072_Material.016" mesh="Circle.165_Material.016"
                pos="0.003239938523620367 -0.3716372549533844 -0.006000056862831116"
                quat="0.7969359159469604 -0.604058027267456 -0.002095800591632724 -0.0016281333519145846"
                type="mesh" material="Material.016" />
              <geom class="collision" name="Circle.072_Material.020" mesh="Circle.165_Material.020"
                pos="0.003239938523620367 -0.3716372549533844 -0.006000056862831116"
                quat="0.7969359159469604 -0.604058027267456 -0.002095800591632724 -0.0016281333519145846"
                type="mesh" material="Material.020" />
              <joint name="l_leg_slide" type="slide" axis="0 -1 0" armature="0.1" damping="0.2" />

              <!-- ball joint -->
              <body name="Circle.074"
                pos="-0.00249325 -0.41100822  0.13427598"
                quat="0.58903702  0.77804802 -0.13388116 -0.17248914">
                <inertial pos="-0.000673554721288383 0.05360925942659378 0.00032271063537336886"
                  mass="1" diaginertia="0.002 0.002 0.002" />
                <geom class="collision" name="Circle.074_Material.020"
                  mesh="Circle.167_Material.020"
                  pos="-0.000673554721288383 0.05360925942659378 0.00032271063537336886"
                  quat="4.920061837765388e-05 -0.9759083390235901 -0.00023231259547173977 0.2181808054447174"
                  type="mesh" material="Material.020" />
                <joint name="l_leg_ball_x" type="hinge" axis="1 0 0" range="-0.5 0.5" />
                <joint name="l_leg_ball_z" type="hinge" axis="0 0 1" range="-0.5 0.5" />

                <!-- wheel -->
                <body name="left_wheel">
                  <inertial pos="0.0017034781631082296 0.11481762677431107 -0.0050855171866714954"
                    mass="1" diaginertia="1e-3 1e-3 1e-3" />
                  <geom class="wheel_collision" name="Object_4.013_Metal.001"
                    mesh="Object_0.005_Metal.001"
                    pos="0.0017034781631082296 0.11481762677431107 -0.0050855171866714954"
                    quat="5.773159728050814e-14 1.0 1.4710455076283324e-14 -4.371138828673793e-08"
                    type="mesh" material="Metal.001" />
                  <geom class="wheel_collision" name="Object_4.013_Wheel_Metal_Dark.001"
                    mesh="Object_0.005_Wheel_Metal_Dark.001"
                    pos="0.0017034781631082296 0.11481762677431107 -0.0050855171866714954"
                    quat="5.773159728050814e-14 1.0 1.4710455076283324e-14 -4.371138828673793e-08"
                    type="mesh" material="Wheel_Metal_Dark.001" />
                  <geom class="wheel_collision" name="Object_4.013_Hub_Plastic.001"
                    mesh="Object_0.005_Hub_Plastic.001"
                    pos="0.0017034781631082296 0.11481762677431107 -0.0050855171866714954"
                    quat="5.773159728050814e-14 1.0 1.4710455076283324e-14 -4.371138828673793e-08"
                    type="mesh" material="Hub_Plastic.001" />
                  <geom class="wheel_collision" name="Object_4.013_Rollers.001"
                    mesh="Object_0.005_Rollers.001"
                    pos="0.0017034781631082296 0.11481762677431107 -0.0050855171866714954"
                    quat="5.773159728050814e-14 1.0 1.4710455076283324e-14 -4.371138828673793e-08"
                    type="mesh" material="Rollers.001" />
                  <geom class="wheel_collision" name="Object_4.013_Wheel_Metal.001"
                    mesh="Object_0.005_Wheel_Metal.001"
                    pos="0.0017034781631082296 0.11481762677431107 -0.0050855171866714954"
                    quat="5.773159728050814e-14 1.0 1.4710455076283324e-14 -4.371138828673793e-08"
                    type="mesh" material="Wheel_Metal.001" />
                  <geom class="wheel_collision" name="Object_4.013_Material.016"
                    mesh="Object_0.005_Material.016"
                    pos="0.0017034781631082296 0.11481762677431107 -0.0050855171866714954"
                    quat="5.773159728050814e-14 1.0 1.4710455076283324e-14 -4.371138828673793e-08"
                    type="mesh" material="Material.016" />
                  <geom class="wheel_collision" name="Object_4.013_Material.017"
                    mesh="Object_0.005_Material.017"
                    pos="0.0017034781631082296 0.11481762677431107 -0.0050855171866714954"
                    quat="5.773159728050814e-14 1.0 1.4710455076283324e-14 -4.371138828673793e-08"
                    type="mesh" material="Material.017" />
                  <geom class="wheel_collision" name="Object_4.013_Kontakt.001"
                    mesh="Object_0.005_Kontakt.001"
                    pos="0.0017034781631082296 0.11481762677431107 -0.0050855171866714954"
                    quat="5.773159728050814e-14 1.0 1.4710455076283324e-14 -4.371138828673793e-08"
                    type="mesh" material="Kontakt.001" />
                  <!-- <geom class="wheel_collision"/> -->

                  <joint class="wheel" name="l_wheel" type="hinge" axis="0 1 0" />
                </body>
              </body>
            </body>

          </body>
        </body>

        <!-- right leg -->
        <body name="Cylinder.035" pos="0.01267889  3.32641149 -0.5750438"
          quat="3.00705850e-01  1.95495986e-07  6.16396606e-08 -9.53716935e-01">
          <inertial pos="0.005107475444674492 0.16674396395683289 -0.014391127042472363"
            mass="0.1" diaginertia="1e-3 1e-3 1e-3" />
          <geom class="collision" name="Cylinder.035_Material.016" mesh="Cylinder.035_Material.016"
            pos="0.005107475444674492 0.16674396395683289 -0.014391127042472363"
            quat="0.16388510167598724 -0.16388536989688873 -0.6878529191017151 0.6878529191017151"
            type="mesh" material="Material.016" />
          <geom class="collision" name="Cylinder.035_Material.017" mesh="Cylinder.035_Material.017"
            pos="0.005107475444674492 0.16674396395683289 -0.014391127042472363"
            quat="0.16388510167598724 -0.16388536989688873 -0.6878529191017151 0.6878529191017151"
            type="mesh" material="Material.017" />
          <geom class="collision" name="Cylinder.035_Kontakt.001" mesh="Cylinder.035_Kontakt.001"
            pos="0.005107475444674492 0.16674396395683289 -0.014391127042472363"
            quat="0.16388510167598724 -0.16388536989688873 -0.6878529191017151 0.6878529191017151"
            type="mesh" material="Kontakt.001" />
          <joint name="r_leg_hinge1" type="hinge" axis="0 0 -1" armature="0.1" damping="0.2" />
          <!-- second hinge joint -->
          <body name="Cylinder.032" pos="8.86807591e-03  3.03966254e-01 -5.40339442e-07"
            quat="0.00441929 -0.01330745 -0.99056299  0.13633906">
            <inertial pos="-0.001063627190887928 0.5253408551216125 -0.004862062633037567"
              mass="0.1" diaginertia="1e-3 1e-3 1e-3" />
            <geom class="collision" name="Cylinder.032_Material.016"
              mesh="Cylinder.032_Material.016"
              pos="-0.001063627190887928 0.5253408551216125 -0.004862062633037567"
              quat="0.778048038482666 0.5890370607376099 0.17248916625976562 0.1338811069726944"
              type="mesh" material="Material.016" />
            <geom class="collision" name="Cylinder.032_Material.017"
              mesh="Cylinder.032_Material.017"
              pos="-0.001063627190887928 0.5253408551216125 -0.004862062633037567"
              quat="0.778048038482666 0.5890370607376099 0.17248916625976562 0.1338811069726944"
              type="mesh" material="Material.017" />
            <joint name="r_leg_hinge2" type="hinge" axis="-1 0 0" armature="0.1" damping="0.2" />

            <!-- linear joint -->
            <body name="Cylinder.034" pos="5.59532765e-07 3.08583133e+00 5.10828367e-07"
              quat="-1.84651279e-08  9.99985822e-01 -3.73061627e-08  5.32507166e-03">
              <inertial pos="4.862714558839798e-05 0.6937386989593506 -0.0009391382336616516"
                mass="0.1" diaginertia="1e-3 1e-3 1e-3" />
              <geom class="collision" name="Cylinder.034_Material.018"
                mesh="Cylinder.034_Material.018"
                pos="4.862714558839798e-05 0.6937386989593506 -0.0009391382336616516"
                quat="0.589741587638855 -0.7771185040473938 0.13074257969856262 -0.17662985622882843"
                type="mesh" material="Material.018" />

              <geom class="collision" name="Circle.073_Material.016" mesh="Circle.166_Material.016"
                pos="0.0024604485370218754 -0.3107270300388336 0.08771117776632309"
                quat="0.6040581464767456 -0.7969357967376709 -0.001588550629094243 -0.0021479586139321327"
                type="mesh" material="Material.016" />
              <geom class="collision" name="Circle.073_Material.020" mesh="Circle.166_Material.020"
                pos="0.0024604485370218754 -0.3107270300388336 0.08771117776632309"
                quat="0.6040581464767456 -0.7969357967376709 -0.001588550629094243 -0.0021479586139321327"
                type="mesh" material="Material.020" />
              <joint name="r_leg_slide" type="slide" axis="0 -1 0" armature="0.1" damping="0.2" />

              <!-- ball joint -->
              <body name="Circle.075" pos="0.0029397  -0.35919264  0.05037501"
                quat="0.50945894 -0.67440156 -0.32456173  0.42461018">
                <inertial pos="-0.002711428329348564 0.11075666546821594 0.0057059526443481445"
                  mass="1" diaginertia="1e-3 1e-3 1e-3" />
                <geom class="collision" name="Circle.075_Material.020"
                  mesh="Circle.168_Material.020"
                  pos="-0.002711428329348564 0.11075666546821594 0.0057059526443481445"
                  quat="0.8441504240036011 -0.0004908267292194068 0.5361055731773376 -0.0007888238760642707"
                  type="mesh" material="Material.020" />
                <joint name="r_leg_ball_x" type="hinge" axis="1 0 0" range="-0.5 0.5" />
                <joint name="r_leg_ball_z" type="hinge" axis="0 0 1" range="-0.5 0.5" />

                <!-- right wheel -->
                <body name="right_wheel" pos="7.13652284e-08  1.91753060e-01 -1.20600845e-07">
                  <inertial pos="0.0050855278968811035 0.10893464833498001 -0.0017036980716511607"
                    mass="0.1" diaginertia="1e-3 1e-3 1e-3" />
                  <geom class="wheel_collision" name="Object_4.014_Metal.001"
                    mesh="Object_0.006_Metal.001"
                    pos="0.0050855278968811035 0.10893464833498001 -0.0017036980716511607"
                    quat="0.7071065902709961 2.370768115156352e-08 0.7071069478988647 -1.3170808443874193e-08"
                    type="mesh" material="Metal.001" />
                  <geom class="wheel_collision" name="Object_4.014_Wheel_Metal_Dark.001"
                    mesh="Object_0.006_Wheel_Metal_Dark.001"
                    pos="0.0050855278968811035 0.10893464833498001 -0.0017036980716511607"
                    quat="0.7071065902709961 2.370768115156352e-08 0.7071069478988647 -1.3170808443874193e-08"
                    type="mesh" material="Wheel_Metal_Dark.001" />
                  <geom class="wheel_collision" name="Object_4.014_Hub_Plastic.001"
                    mesh="Object_0.006_Hub_Plastic.001"
                    pos="0.0050855278968811035 0.10893464833498001 -0.0017036980716511607"
                    quat="0.7071065902709961 2.370768115156352e-08 0.7071069478988647 -1.3170808443874193e-08"
                    type="mesh" material="Hub_Plastic.001" />
                  <geom class="wheel_collision" name="Object_4.014_Rollers.001"
                    mesh="Object_0.006_Rollers.001"
                    pos="0.0050855278968811035 0.10893464833498001 -0.0017036980716511607"
                    quat="0.7071065902709961 2.370768115156352e-08 0.7071069478988647 -1.3170808443874193e-08"
                    type="mesh" material="Rollers.001" />
                  <geom class="wheel_collision" name="Object_4.014_Wheel_Metal.001"
                    mesh="Object_0.006_Wheel_Metal.001"
                    pos="0.0050855278968811035 0.10893464833498001 -0.0017036980716511607"
                    quat="0.7071065902709961 2.370768115156352e-08 0.7071069478988647 -1.3170808443874193e-08"
                    type="mesh" material="Wheel_Metal.001" />
                  <geom class="wheel_collision" name="Object_4.014_Material.016"
                    mesh="Object_0.006_Material.016"
                    pos="0.0050855278968811035 0.10893464833498001 -0.0017036980716511607"
                    quat="0.7071065902709961 2.370768115156352e-08 0.7071069478988647 -1.3170808443874193e-08"
                    type="mesh" material="Material.016" />
                  <geom class="wheel_collision" name="Object_4.014_Material.017"
                    mesh="Object_0.006_Material.017"
                    pos="0.0050855278968811035 0.10893464833498001 -0.0017036980716511607"
                    quat="0.7071065902709961 2.370768115156352e-08 0.7071069478988647 -1.3170808443874193e-08"
                    type="mesh" material="Material.017" />
                  <geom class="wheel_collision" name="Object_4.014_Kontakt.001"
                    mesh="Object_0.006_Kontakt.001"
                    pos="0.0050855278968811035 0.10893464833498001 -0.0017036980716511607"
                    quat="0.7071065902709961 2.370768115156352e-08 0.7071069478988647 -1.3170808443874193e-08"
                    type="mesh" material="Kontakt.001" />

                  <joint class="wheel" name="r_wheel" type="hinge" axis="0 -1 0" />

                </body>
              </body>
            </body>
          </body>
        </body>

        <!-- slide joint to arm 1 -->
        <body name="Cylinder.030" pos="-0.32974637  3.48881432  0.10744319"
          quat="1.0 1.43556846e-09 6.63546772e-08 6.70552266e-08">
          <joint name="arm_column_slide_1" type="slide" axis="0 1 0" />
          <body name="slider_column_1">
            <joint name="arm_column_hinge_1" type="hinge" axis="0 0 1" damping="0.3" armature="0.4" />
            <inertial pos="-1.3273429999571817e-07 1.0633358442646568e-06 1.9925902705608678e-08"
              mass="0.1" diaginertia="1e-3 1e-3 1e-3" />
            <geom class="collision" name="Cylinder.030_Material.017"
              mesh="Cylinder.030_Material.017"
              pos="-1.3273429999571817e-07 1.0633358442646568e-06 1.9925902705608678e-08"
              quat="0.7052982449531555 -0.7052982449531555 -0.050541218370199203 0.050541117787361145"
              type="mesh" material="Material.017" />
          </body>
          <!-- arm -->
          <body name="arm" pos="-0.30935456 -0.04247571 -0.10492611"
            quat="-7.96747621e-08  7.55839428e-01 -6.54757023e-01  1.81477530e-08">
            <joint name="arm_hinge" type="hinge" pos="0.00206806 -0.31225016 -0.10492606"
              axis="0 0 1" />

            <!-- anchor to column2 - cylinder.036 -->
            <body name="anchor_column2" pos="0.00206854 -0.99450253  0.10492496"
              quat="-2.00701104e-09 -7.55839496e-01  6.54756944e-01  5.77943007e-08">
              <joint name="arm_slide_2" type="slide" axis="1 0 0" damping="0.3" />
            </body>

            <!-- wrist -->
            <body name="arm_body">
              <joint name="arm_slide" type="slide" axis="0 1 0" range="-0.8 0.8" />

              <inertial pos="-1.9072597297054017e-06 0.1723650097846985 2.9776984433738107e-08"
                mass="0.001" diaginertia="1e-6 1e-6 1e-6" />

              <geom class="collision" name="Cube.668_Material.018" mesh="Cube.010_Material.018"
                pos="-1.9072597297054017e-06 0.1723650097846985 2.9776984433738107e-08"
                quat="0.5000004172325134 0.5000002980232239 -0.4999997019767761 -0.49999964237213135"
                type="mesh" material="Material.018" />
              <geom class="collision" name="Cube.668_Material.017" mesh="Cube.010_Material.017"
                pos="-1.9072597297054017e-06 0.1723650097846985 2.9776984433738107e-08"
                quat="0.5000004172325134 0.5000002980232239 -0.4999997019767761 -0.49999964237213135"
                type="mesh" material="Material.017" />

              <body name="wrist.004">
                <inertial pos="-0.0008332703146152198 0.7048842310905457 0.03293070197105408"
                  mass="0.001" diaginertia="1e-6 1e-6 1e-6" />
                <geom name="wrist.004_metal.001" mesh="Circle.115_metal.001"
                  pos="-0.0008332703146152198 0.7048842310905457 0.03293070197105408"
                  quat="0.49606993794441223 -0.5025080442428589 0.5038986206054688 0.497480183839798"
                  type="mesh" material="metal.001" />

                <!-- hinge joint 1 -->
                <body name="wrist.005" pos="5.26756416e-11  6.04329288e-01 -9.34570213e-04"
                  quat="1.00000000e+00 -6.82303997e-09  5.55111512e-17 -3.97824551e-11">
                  <inertial pos="0.002095937728881836 0.15128421783447266 6.208895501913503e-05"
                    mass="0.001" diaginertia="1e-6 1e-6 1e-6" />
                  <geom name="wrist.005_metal.001" mesh="Circle.164_metal.001"
                    pos="0.002095937728881836 0.15128421783447266 6.208895501913503e-05"
                    quat="0.5055065155029297 -0.5055071711540222 0.4944315254688263 0.49443212151527405"
                    type="mesh" material="metal.001" />
                  <joint name="wrist_1" type="hinge" axis="0 0 1" armature="0.1" />
                  <!-- gripper body -->
                  <body name="ROBOTIQ.AG3">
                    <joint name="wrist_2" type="hinge" axis="0 1 0" />
                    <inertial pos="0.0021004676818847656 0.1548752784729004 6.934582052053884e-05"
                      mass="0.001" diaginertia="1e-6 1e-6 1e-6" />
                    <geom name="ROBOTIQ.AG3.housing.002_Schwarz_plastik.002"
                      mesh="Cube.090_Schwarz_plastik.002"
                      pos="0.0021004676818847656 0.1548752784729004 6.934582052053884e-05"
                      quat="0.49606993794441223 -0.5025079846382141 0.5038986206054688 0.497480183839798"
                      type="mesh" material="Schwarz_plastik.002" />
                    <geom name="Cylinder.025_LED_Grün.001" mesh="Cylinder.025_LED_Grün.001"
                      pos="0.01696324348449707 0.1548752784729004 2.766708166745957e-05"
                      quat="0.49606993794441223 -0.5025079846382141 0.5038986206054688 0.497480183839798"
                      type="mesh" material="LED_Grün.001" />
                    <geom name="Cylinder.026_LED_Grün.001" mesh="Cylinder.026_LED_Grün.001"
                      pos="-0.012762308120727539 0.1548752784729004 0.00011102269490947947"
                      quat="0.49606993794441223 -0.5025079846382141 0.5038986206054688 0.497480183839798"
                      type="mesh" material="LED_Grün.001" />
                    <geom name="Cylinder.027_LED_Grün.001" mesh="Cylinder.027_LED_Grün.001"
                      pos="0.0021004676818847656 0.1548752784729004 6.934582052053884e-05"
                      quat="0.49606993794441223 -0.5025079846382141 0.5038986206054688 0.497480183839798"
                      type="mesh" material="LED_Grün.001" />
                    <geom name="Cylinder.028_metalAxis.001" mesh="Cylinder.028_metalAxis.001"
                      pos="0.0017652403330430388 0.37027931213378906 -0.14322474598884583"
                      quat="0.49606993794441223 -0.5025079846382141 0.5038986206054688 0.497480183839798"
                      type="mesh" material="metalAxis.001" />
                    <geom name="Gummi.big.brecket.002_metal.001" mesh="Plane.070_metal.001"
                      pos="0.002100706100463867 0.15023016929626465 0.00012908644566778094"
                      quat="0.49606993794441223 -0.5025079846382141 0.5038986206054688 0.497480183839798"
                      type="mesh" material="metal.001" />
                    <geom name="Bolt.002_metal.001" mesh="Bolt.002_metal.001"
                      pos="0.002100706100463867 0.15521657466888428 6.505521741928533e-05"
                      quat="0.49606993794441223 -0.5025079846382141 0.5038986206054688 0.497480183839798"
                      type="mesh" material="metal.001" />
                    <geom name="Gummi-big.002_Gummi.001" mesh="Plane.071_Gummi.001"
                      pos="0.002049206057563424 0.4600660800933838 -0.021941911429166794"
                      quat="0.49606993794441223 -0.5025079846382141 0.5038986206054688 0.497480183839798"
                      type="mesh" material="Gummi.001" />
                    <geom name="Gummi-big.002_metal.001" mesh="Plane.071_metal.001"
                      pos="0.002049206057563424 0.4600660800933838 -0.021941911429166794"
                      quat="0.49606993794441223 -0.5025079846382141 0.5038986206054688 0.497480183839798"
                      type="mesh" material="metal.001" />
                    <geom name="Plug.COM.002_metal.001" mesh="Circle.113_metal.001"
                      pos="0.0762312263250351 0.2656658887863159 -0.1563492715358734"
                      quat="0.49046003818511963 -0.4969664514064789 0.5093607306480408 0.5030159950256348"
                      type="mesh" material="metal.001" />
                    <geom name="Plug.COM.002_Kontakt.001" mesh="Circle.113_Kontakt.001"
                      pos="0.0762312263250351 0.2656658887863159 -0.1563492715358734"
                      quat="0.49046003818511963 -0.4969664514064789 0.5093607306480408 0.5030159950256348"
                      type="mesh" material="Kontakt.001" />
                    <geom name="Plug.COM.002_weiss.001" mesh="Circle.113_weiss.001"
                      pos="0.0762312263250351 0.2656658887863159 -0.1563492715358734"
                      quat="0.49046003818511963 -0.4969664514064789 0.5093607306480408 0.5030159950256348"
                      type="mesh" material="weiss.001" />
                    <geom name="Plug.PWR.002_metal.001" mesh="Circle.114_metal.001"
                      pos="-0.07254816591739655 0.2656656503677368 -0.15593263506889343"
                      quat="0.49046003818511963 -0.4969664514064789 0.5093607306480408 0.5030159950256348"
                      type="mesh" material="metal.001" />
                    <geom name="Plug.PWR.002_Kontakt.001" mesh="Circle.114_Kontakt.001"
                      pos="-0.07254816591739655 0.2656656503677368 -0.15593263506889343"
                      quat="0.49046003818511963 -0.4969664514064789 0.5093607306480408 0.5030159950256348"
                      type="mesh" material="Kontakt.001" />
                    <geom name="Plug.PWR.002_weiss.001" mesh="Circle.114_weiss.001"
                      pos="-0.07254816591739655 0.2656656503677368 -0.15593263506889343"
                      quat="0.49046003818511963 -0.4969664514064789 0.5093607306480408 0.5030159950256348"
                      type="mesh" material="weiss.001" />
                    <geom name="txt.com.002_weiss.001" mesh="Plane.072_weiss.001"
                      pos="0.0021004676818847656 0.1548752784729004 6.934582052053884e-05"
                      quat="0.49606993794441223 -0.5025079846382141 0.5038986206054688 0.497480183839798"
                      type="mesh" material="weiss.001" />
                    <geom name="txt.robotiq.003_weiss.001" mesh="Plane.073_weiss.001"
                      pos="0.0021004676818847656 0.1548752784729004 6.934582052053884e-05"
                      quat="0.49606993794441223 -0.5025079846382141 0.5038986206054688 0.497480183839798"
                      type="mesh" material="weiss.001" />
                    <geom name="USB.002_Schwarz_plastik.002"
                      mesh="Unten_pcbV1000-A.003_Schwarz_plastik.002"
                      pos="0.0016252865316346288 0.2760961055755615 -0.16962511837482452"
                      quat="0.4260540008544922 -0.5631431341171265 0.5643378496170044 0.42763370275497437"
                      type="mesh" material="Schwarz_plastik.002" />
                    <geom name="USB.002_metal.001" mesh="Unten_pcbV1000-A.003_metal.001"
                      pos="0.0016252865316346288 0.2760961055755615 -0.16962511837482452"
                      quat="0.4260540008544922 -0.5631431341171265 0.5643378496170044 0.42763370275497437"
                      type="mesh" material="metal.001" />
                    <geom name="USB.002_Gold.001" mesh="Unten_pcbV1000-A.003_Gold.001"
                      pos="0.0016252865316346288 0.2760961055755615 -0.16962511837482452"
                      quat="0.4260540008544922 -0.5631431341171265 0.5643378496170044 0.42763370275497437"
                      type="mesh" material="Gold.001" />
                    <geom name="USB.002_Blau_plastik.USB.001"
                      mesh="Unten_pcbV1000-A.003_Blau_plastik.USB.001"
                      pos="0.0016252865316346288 0.2760961055755615 -0.16962511837482452"
                      quat="0.4260540008544922 -0.5631431341171265 0.5643378496170044 0.42763370275497437"
                      type="mesh" material="Blau_plastik.USB.001" />
                    <!-- finger 1 base -->
                    <body name="Finger.1.Base.006">
                      <inertial pos="0.001826515537686646 0.3705606460571289 -0.1213536337018013"
                        mass="0.001" diaginertia="1e-6 1e-6 1e-6" />
                      <geom name="Finger.1.Base.006_metal.Black.001"
                        mesh="Circle.006_metal.Black.001"
                        pos="0.001826515537686646 0.3705606460571289 -0.1213536337018013"
                        quat="0.4974803626537323 -0.5038984417915344 -0.5025078058242798 -0.4960700571537018"
                        type="mesh" material="metal.Black.001" />

                      <geom name="Axis.067_metalAxis.001" mesh="Cube.091_metalAxis.001"
                        pos="0.0017917054938152432 0.433361291885376 -0.13377557694911957"
                        quat="0.49748024344444275 -0.503898561000824 -0.5025079250335693 -0.496069997549057"
                        type="mesh" material="metalAxis.001" />

                      <!-- finger 1 -->
                      <body name="finger_1" pos="0.0017948   0.43336141 -0.13377561">
                        <inertial
                          pos="0.026081552729010582 1.966951458598487e-05 -0.0001950038131326437"
                          mass="0.001" diaginertia="1e-6 1e-6 1e-6" />
                        <geom name="Circle.048_metal.Black.001" mesh="Circle.116_metal.Black.001"
                          pos="0.026081552729010582 1.966951458598487e-05 -0.0001950038131326437"
                          quat="0.4983198344707489 0.504242479801178 -0.5014793872833252 0.4959186315536499"
                          type="mesh" material="metal.Black.001" />
                        <geom name="Circle.049_metal.Black.001" mesh="Circle.117_metal.Black.001"
                          pos="-0.02569199539721012 -1.668947447797109e-06 7.214811921585351e-05"
                          quat="0.4989202618598938 -0.5036441683769226 -0.5012727379798889 -0.49613186717033386"
                          type="mesh" material="metal.Black.001" />

                        <geom name="Axis.070_metalAxis.001" mesh="Cube.094_metalAxis.001"
                          pos="-0.0001266106410184875 0.27649223804473877 -0.0027881169226020575"
                          quat="0.4989204406738281 -0.5036441087722778 -0.5012726783752441 -0.49613186717033386"
                          type="mesh" material="metalAxis.001" />
                        <geom name="Axis.071_metalAxis.001" mesh="Cube.096_metalAxis.001"
                          pos="-5.19855493621435e-05 0.1665879487991333 -0.001717513077892363"
                          quat="0.4989202618598938 -0.5036441683769226 -0.5012728571891785 -0.4961317479610443"
                          type="mesh" material="metalAxis.001" />
                        <geom name="Axis.072_metalAxis.001" mesh="Circle.118_metalAxis.001"
                          pos="0.020779119804501534 0.2876368761062622 -0.038910575211048126"
                          quat="0.4989202618598938 -0.5036442279815674 -0.5012727379798889 -0.4961318075656891"
                          type="mesh" material="metalAxis.001" />
                        <geom name="Axis.073_metalAxis.001" mesh="Circle.119_metalAxis.001"
                          pos="0.021318184211850166 0.17624962329864502 -0.037753961980342865"
                          quat="0.4989202618598938 -0.5036442279815674 -0.5012727379798889 -0.4961318075656891"
                          type="mesh" material="metalAxis.001" />
                        <geom name="Axis.074_metalAxis.001" mesh="Circle.120_metalAxis.001"
                          pos="0.021304354071617126 0.16641390323638916 -0.06892023235559464"
                          quat="0.498920202255249 -0.5036443471908569 -0.5012727975845337 -0.49613162875175476"
                          type="mesh" material="metalAxis.001" />
                        <geom name="Axis.075_metalAxis.001" mesh="Circle.121_metalAxis.001"
                          pos="-0.02209688536822796 0.2876197099685669 -0.03868917003273964"
                          quat="0.4989203214645386 -0.5036442279815674 -0.5012727379798889 -0.4961317479610443"
                          type="mesh" material="metalAxis.001" />
                        <geom name="Axis.076_metalAxis.001" mesh="Circle.122_metalAxis.001"
                          pos="-0.02155853621661663 0.1762329339981079 -0.03753257170319557"
                          quat="0.4989202618598938 -0.5036442279815674 -0.5012727379798889 -0.4961318075656891"
                          type="mesh" material="metalAxis.001" />
                        <geom name="Axis.077_metalAxis.001" mesh="Circle.123_metalAxis.001"
                          pos="-0.021572604775428772 0.16639816761016846 -0.06869897246360779"
                          quat="0.4989202618598938 -0.5036442279815674 -0.5012727379798889 -0.4961318075656891"
                          type="mesh" material="metalAxis.001" />
                        <geom name="Axis.078_metalAxis.001" mesh="Circle.124_metalAxis.001"
                          pos="-0.021342525258660316 1.1919193809717399e-07 4.975134652340785e-05"
                          quat="0.4989202618598938 -0.5036441683769226 -0.5012727379798889 -0.49613186717033386"
                          type="mesh" material="metalAxis.001" />
                        <geom name="Circle.050_metal.Black.001" mesh="Circle.125_metal.Black.001"
                          pos="0.03492091968655586 0.17625534534454346 -0.03782414644956589"
                          quat="0.4989203214645386 -0.5036442279815674 -0.5012727379798889 -0.4961317479610443"
                          type="mesh" material="metal.Black.001" />
                        <geom name="Circle.051_metal.Black.001" mesh="Circle.126_metal.Black.001"
                          pos="0.01730130985379219 0.16659414768218994 -0.001807025633752346"
                          quat="0.4989203214645386 -0.5036441683769226 -0.5012727379798889 -0.49613186717033386"
                          type="mesh" material="metal.Black.001" />
                        <geom name="Circle.052_metal.Black.001" mesh="Circle.127_metal.Black.001"
                          pos="0.0170280784368515 -0.0003851652436424047 -0.06732203811407089"
                          quat="0.4989202618598938 -0.5036442875862122 -0.5012727975845337 -0.49613168835639954"
                          type="mesh" material="metal.Black.001" />
                        <geom name="Axis.079_metalAxis.001" mesh="Circle.128_metalAxis.001"
                          pos="0.02146386168897152 1.5139562492549885e-05 -0.00017128081526607275"
                          quat="0.4989202618598938 -0.5036442875862122 -0.5012727975845337 -0.49613168835639954"
                          type="mesh" material="metalAxis.001" />
                        <geom name="Circle.053_metal.Black.001" mesh="Circle.129_metal.Black.001"
                          pos="-0.02652217261493206 0.1762310266494751 -0.03750695660710335"
                          quat="0.4989202618598938 -0.5036442279815674 -0.5012727379798889 -0.4961318075656891"
                          type="mesh" material="metal.Black.001" />
                        <geom name="Circle.054_metal.Black.001" mesh="Circle.130_metal.Black.001"
                          pos="-0.025575410574674606 0.16657745838165283 -0.0015857700491324067"
                          quat="0.4989203214645386 -0.5036441683769226 -0.5012727379798889 -0.49613186717033386"
                          type="mesh" material="metal.Black.001" />
                        <geom name="Circle.055_metal.Black.001" mesh="Circle.131_metal.Black.001"
                          pos="-0.025848880410194397 -0.0004010200791526586 -0.06710076332092285"
                          quat="0.4989203214645386 -0.5036441683769226 -0.5012727379798889 -0.49613186717033386"
                          type="mesh" material="metal.Black.001" />
                        <geom name="Finger.1.019_metal.Black.001" mesh="Plane.074_metal.Black.001"
                          pos="-0.0001266106410184875 0.27649176120758057 -0.0027881169226020575"
                          quat="0.4989203214645386 -0.5036441683769226 -0.5012727379798889 -0.49613186717033386"
                          type="mesh" material="metal.Black.001" />
                        <geom name="Finger.1.019_Gummi.001" mesh="Plane.074_Gummi.001"
                          pos="-0.0001266106410184875 0.27649176120758057 -0.0027881169226020575"
                          quat="0.4989203214645386 -0.5036441683769226 -0.5012727379798889 -0.49613186717033386"
                          type="mesh" material="Gummi.001" />
                        <geom name="Finger.1.019_metal.001" mesh="Plane.074_metal.001"
                          pos="-0.0001266106410184875 0.27649176120758057 -0.0027881169226020575"
                          quat="0.4989203214645386 -0.5036441683769226 -0.5012727379798889 -0.49613186717033386"
                          type="mesh" material="metal.001" />
                        <geom name="Finger.1.020_metal.Black.001" mesh="Cube.097_metal.Black.001"
                          pos="-7.773475226713344e-05 0.16656839847564697 -0.0017035208875313401"
                          quat="0.4989203214645386 -0.5036441683769226 -0.5012727379798889 -0.49613186717033386"
                          type="mesh" material="metal.Black.001" />
                        <geom name="Finger.1.020_metal.001" mesh="Cube.097_metal.001"
                          pos="-7.773475226713344e-05 0.16656839847564697 -0.0017035208875313401"
                          quat="0.4989203214645386 -0.5036441683769226 -0.5012727379798889 -0.49613186717033386"
                          type="mesh" material="metal.001" />
                        <geom name="Finger.1.020_Gummi.001" mesh="Cube.097_Gummi.001"
                          pos="-7.773475226713344e-05 0.16656839847564697 -0.0017035208875313401"
                          quat="0.4989203214645386 -0.5036441683769226 -0.5012727379798889 -0.49613186717033386"
                          type="mesh" material="Gummi.001" />
                        <geom name="Finger.1.021_metal.Black.001" mesh="Cube.098_metal.Black.001"
                          pos="-4.063290816702647e-06 8.702260856807698e-06 -6.057846258045174e-05"
                          quat="0.49897441267967224 -0.5035905241966248 -0.5013279914855957 -0.49607595801353455"
                          type="mesh" material="metal.Black.001" />
                        <geom name="Finger.1.021_metal.001" mesh="Cube.098_metal.001"
                          pos="-4.063290816702647e-06 8.702260856807698e-06 -6.057846258045174e-05"
                          quat="0.49897441267967224 -0.5035905241966248 -0.5013279914855957 -0.49607595801353455"
                          type="mesh" material="metal.001" />
                        <geom name="Finger.1.021_Gummi.001" mesh="Cube.098_Gummi.001"
                          pos="-4.063290816702647e-06 8.702260856807698e-06 -6.057846258045174e-05"
                          quat="0.49897441267967224 -0.5035905241966248 -0.5013279914855957 -0.49607595801353455"
                          type="mesh" material="Gummi.001" />
                        <joint name="finger_1" type="hinge" axis="1 0 0" />
                      </body>
                    </body>

                    <!-- finger 2 base -->
                    <body name="Finger.1.Base.007">
                      <inertial pos="-0.1045060083270073 0.3736119270324707 0.11629840731620789"
                        mass="0.001" diaginertia="1e-6 1e-6 1e-6" />
                      <geom name="Finger.1.Base.007_metal.Black.001"
                        mesh="Circle.111_metal.Black.001"
                        pos="-0.1045060083270073 0.3736119270324707 0.11629840731620789"
                        quat="0.49606993794441223 -0.5025079846382141 0.5038986206054688 0.497480183839798"
                        type="mesh" material="metal.Black.001" />
                      <geom name="Axis.068_metalAxis.001" mesh="Cube.092_metalAxis.001"
                        pos="-0.1044754907488823 0.43671131134033203 0.12710174918174744"
                        quat="0.49606993794441223 -0.5025079846382141 0.5038986206054688 0.497480183839798"
                        type="mesh" material="metalAxis.001" />
                      <!-- finger 2 -->
                      <body name="finger 2"
                        pos="-0.10447239  0.43671167  0.12710172"
                        quat="9.80437398e-01 -1.96831167e-01 -9.26719701e-10  1.02442286e-08">
                        <inertial
                          pos="0.001524018938653171 0.27665358781814575 0.0020455375779420137"
                          mass="0.001" diaginertia="1e-6 1e-6 1e-6" />
                        <geom name="Axis.080_metalAxis.001" mesh="Cube.099_metalAxis.001"
                          pos="0.001524018938653171 0.27665358781814575 0.0020455375779420137"
                          quat="0.5066111087799072 -0.4994557499885559 0.49614349007606506 0.49772563576698303"
                          type="mesh" material="metalAxis.001" />
                        <geom name="Axis.081_metalAxis.001" mesh="Cube.100_metalAxis.001"
                          pos="0.0008917338564060628 0.16674989461898804 0.0010944782989099622"
                          quat="0.5066111087799072 -0.4994558095932007 0.49614349007606506 0.4977256953716278"
                          type="mesh" material="metalAxis.001" />
                        <geom name="Axis.082_metalAxis.001" mesh="Circle.132_metalAxis.001"
                          pos="-0.019945332780480385 0.28795135021209717 0.03778795525431633"
                          quat="0.5066111087799072 -0.4994557499885559 0.49614349007606506 0.49772563576698303"
                          type="mesh" material="metalAxis.001" />
                        <geom name="Axis.083_metalAxis.001" mesh="Circle.133_metalAxis.001"
                          pos="-0.021049687638878822 0.1765661984682083 0.03674447163939476"
                          quat="0.5066111087799072 -0.4994557499885559 0.49614349007606506 0.49772563576698303"
                          type="mesh" material="metalAxis.001" />
                        <geom name="Axis.084_metalAxis.001" mesh="Circle.134_metalAxis.001"
                          pos="-0.021627133712172508 0.16676874458789825 0.06791713833808899"
                          quat="0.5066111087799072 -0.4994557499885559 0.49614349007606506 0.4977256953716278"
                          type="mesh" material="metalAxis.001" />
                        <geom name="Axis.085_metalAxis.001" mesh="Circle.135_metalAxis.001"
                          pos="0.022927096113562584 0.28770911693573 0.0383099690079689"
                          quat="0.5066111087799072 -0.4994557499885559 0.49614349007606506 0.49772563576698303"
                          type="mesh" material="metalAxis.001" />
                        <geom name="Axis.086_metalAxis.001" mesh="Circle.136_metalAxis.001"
                          pos="0.021824171766638756 0.17632482945919037 0.03726648539304733"
                          quat="0.5066111087799072 -0.4994557499885559 0.49614349007606506 0.49772563576698303"
                          type="mesh" material="metalAxis.001" />
                        <geom name="Axis.087_metalAxis.001" mesh="Circle.137_metalAxis.001"
                          pos="0.02124696411192417 0.1665283441543579 0.06843920052051544"
                          quat="0.5066111087799072 -0.4994557499885559 0.49614349007606506 0.49772563576698303"
                          type="mesh" material="metalAxis.001" />
                        <geom name="Circle.056_metal.Black.001" mesh="Circle.138_metal.Black.001"
                          pos="-0.034651465713977814 0.17664311826229095 0.03657900542020798"
                          quat="0.5066111087799072 -0.4994557499885559 0.49614349007606506 0.49772563576698303"
                          type="mesh" material="metal.Black.001" />
                        <geom name="Circle.057_metal.Black.001" mesh="Circle.139_metal.Black.001"
                          pos="-0.0164610855281353 0.16684749722480774 0.0008833190076984465"
                          quat="0.5066111087799072 -0.4994557499885559 0.49614349007606506 0.49772563576698303"
                          type="mesh" material="metal.Black.001" />
                        <geom name="Circle.058_metal.Black.001" mesh="Circle.140_metal.Black.001"
                          pos="-0.018199151381850243 -5.20576759299729e-05 0.06657665222883224"
                          quat="0.5066111087799072 -0.4994557499885559 0.49614349007606506 0.4977256953716278"
                          type="mesh" material="metal.Black.001" />
                        <geom name="Axis.088_metalAxis.001" mesh="Circle.141_metalAxis.001"
                          pos="-0.021468350663781166 0.0002916636585723609 -0.0006412817165255547"
                          quat="0.5066111087799072 -0.4994557499885559 0.49614349007606506 0.4977256953716278"
                          type="mesh" material="metalAxis.001" />
                        <geom name="Circle.059_metal.Black.001" mesh="Circle.142_metal.Black.001"
                          pos="0.026787569746375084 0.1762969195842743 0.037326812744140625"
                          quat="0.5066111087799072 -0.4994557499885559 0.49614349007606506 0.49772563576698303"
                          type="mesh" material="metal.Black.001" />
                        <geom name="Circle.060_metal.Black.001" mesh="Circle.143_metal.Black.001"
                          pos="0.02641301229596138 0.16660641133785248 0.001405281131155789"
                          quat="0.5066111087799072 -0.4994557499885559 0.49614349007606506 0.49772563576698303"
                          type="mesh" material="metal.Black.001" />
                        <geom name="Circle.061_metal.Black.001" mesh="Circle.144_metal.Black.001"
                          pos="0.02467518486082554 -0.00029290473321452737 0.06709867715835571"
                          quat="0.5066111087799072 -0.4994557499885559 0.49614349007606506 0.49772563576698303"
                          type="mesh" material="metal.Black.001" />
                        <geom name="Finger.1.022_metal.Black.001" mesh="Plane.075_metal.Black.001"
                          pos="0.001524018938653171 0.27665388584136963 0.00204554689116776"
                          quat="0.5066111087799072 -0.4994557499885559 0.49614349007606506 0.49772563576698303"
                          type="mesh" material="metal.Black.001" />
                        <geom name="Finger.1.022_Gummi.001" mesh="Plane.075_Gummi.001"
                          pos="0.001524018938653171 0.27665388584136963 0.00204554689116776"
                          quat="0.5066111087799072 -0.4994557499885559 0.49614349007606506 0.49772563576698303"
                          type="mesh" material="Gummi.001" />
                        <geom name="Finger.1.022_metal.001" mesh="Plane.075_metal.001"
                          pos="0.001524018938653171 0.27665388584136963 0.00204554689116776"
                          quat="0.5066111087799072 -0.4994557499885559 0.49614349007606506 0.49772563576698303"
                          type="mesh" material="metal.001" />
                        <geom name="Finger.1.023_metal.Black.001" mesh="Cube.101_metal.Black.001"
                          pos="0.00091724464436993 0.16673113405704498 0.0010810821549966931"
                          quat="0.5066111087799072 -0.4994557499885559 0.49614349007606506 0.49772563576698303"
                          type="mesh" material="metal.Black.001" />
                        <geom name="Finger.1.023_metal.001" mesh="Cube.101_metal.001"
                          pos="0.00091724464436993 0.16673113405704498 0.0010810821549966931"
                          quat="0.5066111087799072 -0.4994557499885559 0.49614349007606506 0.49772563576698303"
                          type="mesh" material="metal.001" />
                        <geom name="Finger.1.023_Gummi.001" mesh="Cube.101_Gummi.001"
                          pos="0.00091724464436993 0.16673113405704498 0.0010810821549966931"
                          quat="0.5066111087799072 -0.4994557499885559 0.49614349007606506 0.49772563576698303"
                          type="mesh" material="Gummi.001" />
                        <geom name="Finger.1.024_metal.Black.001" mesh="Cube.102_metal.Black.001"
                          pos="-2.0959560060873628e-06 0.00017122150165960193 -0.00037985737435519695"
                          quat="0.5045204758644104 -0.501567542552948 0.49405187368392944 0.4998018741607666"
                          type="mesh" material="metal.Black.001" />
                        <geom name="Finger.1.024_metal.001" mesh="Cube.102_metal.001"
                          pos="-2.0959560060873628e-06 0.00017122150165960193 -0.00037985737435519695"
                          quat="0.5045204758644104 -0.501567542552948 0.49405187368392944 0.4998018741607666"
                          type="mesh" material="metal.001" />
                        <geom name="Finger.1.024_Gummi.001" mesh="Cube.102_Gummi.001"
                          pos="-2.0959560060873628e-06 0.00017122150165960193 -0.00037985737435519695"
                          quat="0.5045204758644104 -0.501567542552948 0.49405187368392944 0.4998018741607666"
                          type="mesh" material="Gummi.001" />
                        <geom name="Circle.062_metal.Black.001" mesh="Circle.145_metal.Black.001"
                          pos="-0.017189690843224525 0.00026798201724886894 -0.0005889864405617118"
                          quat="0.5066111087799072 -0.4994558095932007 0.49614349007606506 0.4977256953716278"
                          type="mesh" material="metal.Black.001" />
                        <geom name="Circle.063_metal.Black.001" mesh="Circle.146_metal.Black.001"
                          pos="0.02568393014371395 2.6777332095662132e-05 -6.706903513986617e-05"
                          quat="0.5066111087799072 -0.4994558095932007 0.49614349007606506 0.4977256953716278"
                          type="mesh" material="metal.Black.001" />
                        <geom name="Axis.089_metalAxis.001" mesh="Circle.147_metalAxis.001"
                          pos="0.021334698423743248 5.119284469401464e-05 -0.00012004233576590195"
                          quat="0.5066111087799072 -0.4994558095932007 0.49614349007606506 0.4977256953716278"
                          type="mesh" material="metalAxis.001" />
                        <joint name="finger_2" type="hinge" axis="-1 0 0" />

                      </body>
                    </body>

                    <!-- finger 3 base-->
                    <body name="Finger.1.Base.008">
                      <inertial pos="0.10928083211183548 0.37361228466033936 0.11569957435131073"
                        mass="0.001" diaginertia="1e-6 1e-6 1e-6" />
                      <geom name="Finger.1.Base.008_metal.Black.001"
                        mesh="Circle.112_metal.Black.001"
                        pos="0.10928083211183548 0.37361228466033936 0.11569957435131073"
                        quat="0.49606993794441223 -0.5025079846382141 0.5038986206054688 0.497480183839798"
                        type="mesh" material="metal.Black.001" />
                      <geom name="Axis.069_metalAxis.001" mesh="Cube.093_metalAxis.001"
                        pos="0.10931111127138138 0.4367116689682007 0.12650291621685028"
                        quat="0.49606993794441223 -0.5025079846382141 0.5038986206054688 0.497480183839798"
                        type="mesh" material="metalAxis.001" />
                      <!-- finger 3 -->
                      <body name="Bone.012_Armature.002"
                        pos="0.10931421 0.43671167 0.12650289"
                        quat="9.79817924e-01 -1.99892058e-01 -9.85968918e-10  1.02585149e-08">
                        <inertial pos="-0.018681714311242104 0.2875118851661682 0.042353305965662"
                          mass="0.001" diaginertia="1e-6 1e-6 1e-6" />
                        <geom name="Axis.090_metalAxis.001" mesh="Circle.148_metalAxis.001"
                          pos="-0.018681714311242104 0.2875118851661682 0.042353305965662"
                          quat="0.515640914440155 -0.4964893162250519 0.49005600810050964 0.49745145440101624"
                          type="mesh" material="metalAxis.001" />
                        <geom name="Axis.091_metalAxis.001" mesh="Circle.149_metalAxis.001"
                          pos="0.02417903207242489 0.2869938015937805 0.04340214282274246"
                          quat="0.515640914440155 -0.4964893162250519 0.49005600810050964 0.49745145440101624"
                          type="mesh" material="metalAxis.001" />
                        <geom name="Axis.092_metalAxis.001" mesh="Cube.103_metalAxis.001"
                          pos="0.0031648159492760897 0.27671825885772705 0.006683745887130499"
                          quat="0.515640914440155 -0.4964893162250519 0.49005600810050964 0.49745145440101624"
                          type="mesh" material="metalAxis.001" />
                        <geom name="Axis.093_metalAxis.001" mesh="Circle.150_metalAxis.001"
                          pos="-0.021468346938490868 0.16582556068897247 0.07029152661561966"
                          quat="0.515640914440155 -0.4964893162250519 0.49005600810050964 0.49745145440101624"
                          type="mesh" material="metalAxis.001" />
                        <geom name="Axis.094_metalAxis.001" mesh="Circle.151_metalAxis.001"
                          pos="-0.02044219709932804 0.17617261409759521 0.039308350533246994"
                          quat="0.515640914440155 -0.4964893162250519 0.49005600810050964 0.49745145440101624"
                          type="mesh" material="metalAxis.001" />
                        <geom name="Axis.095_metalAxis.001" mesh="Circle.152_metalAxis.001"
                          pos="0.021392637863755226 0.16530874371528625 0.0713403970003128"
                          quat="0.515640914440155 -0.4964893162250519 0.49005600810050964 0.49745145440101624"
                          type="mesh" material="metalAxis.001" />
                        <geom name="Axis.096_metalAxis.001" mesh="Circle.153_metalAxis.001"
                          pos="0.022419026121497154 0.1756545454263687 0.040357254445552826"
                          quat="0.515640914440155 -0.4964893162250519 0.49005600810050964 0.49745145440101624"
                          type="mesh" material="metalAxis.001" />
                        <geom name="Axis.097_metalAxis.001" mesh="Cube.104_metalAxis.001"
                          pos="0.001882840064354241 0.1668553352355957 0.0037634612526744604"
                          quat="0.515640914440155 -0.4964893162250519 0.49005600810050964 0.49745145440101624"
                          type="mesh" material="metalAxis.001" />
                        <geom name="Circle.064_metal.Black.001" mesh="Circle.154_metal.Black.001"
                          pos="-0.03404016047716141 0.1763371229171753 0.038975540548563004"
                          quat="0.5156408548355103 -0.49648937582969666 0.49005600810050964 0.497451514005661"
                          type="mesh" material="metal.Black.001" />
                        <geom name="Circle.065_metal.Black.001" mesh="Circle.155_metal.Black.001"
                          pos="-0.015464257448911667 0.16706451773643494 0.0033389285672456026"
                          quat="0.515640914440155 -0.4964893162250519 0.49005600810050964 0.49745145440101624"
                          type="mesh" material="metal.Black.001" />
                        <geom name="Circle.066_metal.Black.001" mesh="Circle.156_metal.Black.001"
                          pos="-0.019027894362807274 -0.0009632931905798614 0.0660160481929779"
                          quat="0.5156408548355103 -0.49648937582969666 0.49005600810050964 0.497451514005661"
                          type="mesh" material="metal.Black.001" />
                        <geom name="Axis.098_metalAxis.001" mesh="Circle.157_metalAxis.001"
                          pos="-0.021454760804772377 0.0005952714127488434 -0.001220506033860147"
                          quat="0.5156408548355103 -0.49648937582969666 0.49005600810050964 0.497451514005661"
                          type="mesh" material="metalAxis.001" />
                        <geom name="Circle.067_metal.Black.001" mesh="Circle.158_metal.Black.001"
                          pos="0.027380993589758873 0.1755945384502411 0.040478624403476715"
                          quat="0.515640914440155 -0.4964893162250519 0.49005600810050964 0.49745145440101624"
                          type="mesh" material="metal.Black.001" />
                        <geom name="Circle.068_metal.Black.001" mesh="Circle.159_metal.Black.001"
                          pos="0.02739696577191353 0.16654649376869202 0.004387728404253721"
                          quat="0.515640914440155 -0.4964893162250519 0.49005600810050964 0.49745145440101624"
                          type="mesh" material="metal.Black.001" />
                        <geom name="Circle.069_metal.Black.001" mesh="Circle.160_metal.Black.001"
                          pos="0.02383309230208397 -0.001480236416682601 0.06706488132476807"
                          quat="0.515640914440155 -0.4964893162250519 0.49005600810050964 0.49745145440101624"
                          type="mesh" material="metal.Black.001" />
                        <geom name="Finger.1.025_metal.Black.001" mesh="Plane.076_metal.Black.001"
                          pos="0.0031648159492760897 0.27671825885772705 0.006683745887130499"
                          quat="0.515640914440155 -0.49648919701576233 0.49005600810050964 0.4974516034126282"
                          type="mesh" material="metal.Black.001" />
                        <geom name="Finger.1.025_Gummi.001" mesh="Plane.076_Gummi.001"
                          pos="0.0031648159492760897 0.27671825885772705 0.006683745887130499"
                          quat="0.515640914440155 -0.49648919701576233 0.49005600810050964 0.4974516034126282"
                          type="mesh" material="Gummi.001" />
                        <geom name="Finger.1.025_metal.001" mesh="Plane.076_metal.001"
                          pos="0.0031648159492760897 0.27671825885772705 0.006683745887130499"
                          quat="0.515640914440155 -0.49648919701576233 0.49005600810050964 0.4974516034126282"
                          type="mesh" material="metal.001" />
                        <geom name="Finger.1.026_metal.Black.001" mesh="Cube.105_metal.Black.001"
                          pos="0.0019088276894763112 0.166836217045784 0.0037498900201171637"
                          quat="0.515640914440155 -0.4964893162250519 0.49005600810050964 0.49745145440101624"
                          type="mesh" material="metal.Black.001" />
                        <geom name="Finger.1.026_metal.001" mesh="Cube.105_metal.001"
                          pos="0.0019088276894763112 0.166836217045784 0.0037498900201171637"
                          quat="0.515640914440155 -0.4964893162250519 0.49005600810050964 0.49745145440101624"
                          type="mesh" material="metal.001" />
                        <geom name="Finger.1.026_Gummi.001" mesh="Cube.105_Gummi.001"
                          pos="0.0019088276894763112 0.166836217045784 0.0037498900201171637"
                          quat="0.515640914440155 -0.4964893162250519 0.49005600810050964 0.49745145440101624"
                          type="mesh" material="Gummi.001" />
                        <geom name="Finger.1.027_metal.Black.001" mesh="Cube.106_metal.Black.001"
                          pos="5.2950449571653735e-06 0.00033714252640493214 -0.0006952565745450556"
                          quat="0.5136464834213257 -0.4985524117946625 0.48799920082092285 0.4994693398475647"
                          type="mesh" material="metal.Black.001" />
                        <geom name="Finger.1.027_metal.001" mesh="Cube.106_metal.001"
                          pos="5.2950449571653735e-06 0.00033714252640493214 -0.0006952565745450556"
                          quat="0.5136464834213257 -0.4985524117946625 0.48799920082092285 0.4994693398475647"
                          type="mesh" material="metal.001" />
                        <geom name="Finger.1.027_Gummi.001" mesh="Cube.106_Gummi.001"
                          pos="5.2950449571653735e-06 0.00033714252640493214 -0.0006952565745450556"
                          quat="0.5136464834213257 -0.4985524117946625 0.48799920082092285 0.4994693398475647"
                          type="mesh" material="Gummi.001" />
                        <!-- </body> -->
                        <geom name="Circle.070_metal.Black.001" mesh="Circle.161_metal.Black.001"
                          pos="-0.017177293077111244 0.0005449018208310008 -0.0011157585540786386"
                          quat="0.515640914440155 -0.4964893162250519 0.49005600810050964 0.49745145440101624"
                          type="mesh" material="metal.Black.001" />
                        <geom name="Circle.071_metal.Black.001" mesh="Circle.162_metal.Black.001"
                          pos="0.02568393014371395 2.6863346647587605e-05 -6.69510627631098e-05"
                          quat="0.515640914440155 -0.4964893162250519 0.49005600810050964 0.49745145440101624"
                          type="mesh" material="metal.Black.001" />
                        <geom name="Axis.099_metalAxis.001" mesh="Circle.163_metalAxis.001"
                          pos="0.021335890516638756 7.948302663862705e-05 -0.00017336738528683782"
                          quat="0.515640914440155 -0.4964893162250519 0.49005600810050964 0.49745145440101624"
                          type="mesh" material="metalAxis.001" />
                        <joint name="finger_3" type="hinge" axis="-1 0 0" />
                      </body>
                    </body>
                  </body>

                </body>
              </body>
            </body>
          </body>

        </body>
        <!-- slide joint to arm 2 -->
        <body name="Cylinder.036" pos="0.34553503  3.58609392 -0.10240782"
          quat="1.00000000e+00  1.04163312e-08 -4.18988210e-08 -3.72528324e-08">
          <joint name="arm_column_slide_2" type="slide" axis="0 1 0" />
          <joint name="arm_column_hinge_2" type="hinge" axis="0 0 -1" damping="0.3" armature="0.4" />

          <inertial pos="-0.6752817034721375 -0.0972784161567688 0.20985116064548492"
            mass="0.1" diaginertia="1e-3 1e-3 1e-3" />
          <geom class="collision" name="Cylinder.036_Material.017"
            mesh="Cylinder.036_Material.017"
            pos="-0.6752817034721375 -0.0972784161567688 0.20985116064548492"
            quat="0.7052982449531555 -0.7052982449531555 -0.05054113268852234 0.05054119974374771"
            type="mesh" material="Material.017" />
        </body>
      </body>
    </body>
  </worldbody>
  <equality>
    <connect name="arm_to_column2" body1="Cylinder.036" body2="anchor_column2" anchor="0.0 0.0 0.0"
      solref="0.005 1" solimp="0.99 0.999 0.001" />
    <joint name="slider_arm_1" joint1="arm_column_hinge_1" joint2="arm_hinge" solref="0.02 1"
      solimp="0.99 0.999 0.001" polycoef="0 -1 0 0 0" />
    <joint name="slider_arm_2" joint1="arm_column_hinge_2" joint2="arm_hinge" solref="0.02 1"
      solimp="0.99 0.999 0.001" />

  </equality>

  <contact>
    <exclude body1="arm_body" body2="obotx_frame_legs" />
    <exclude body1="arm_body" body2="Cylinder.023" />

    <exclude body1="arm_body" body2="Cylinder.030" />
    <exclude body1="arm_body" body2="Cylinder.036" />
    <exclude body1="arm_body" body2="slider_column_1" />

    <!-- right leg and base -->
    <exclude body1="Cylinder.023" body2="Cylinder.032" />
    <!-- left leg and base -->
    <exclude body1="Cylinder.023" body2="Cylinder.031" />
    <exclude body1="Cylinder.023" body2="slider_column_1" />
    <!-- wheel and hub -->
    <exclude body1="Cylinder.034" body2="right_wheel" />

    <exclude body1="Cylinder.023" body2="wrist.004" />

  </contact>

  <asset>
    <mesh name="Cylinder.002_Material.016" file="Cylinder.002_Material.016.msh" />
    <mesh name="Cylinder.002_Material.017" file="Cylinder.002_Material.017.msh" />
    <mesh name="Cylinder.002_Kontakt.001" file="Cylinder.002_Kontakt.001.msh" />
    <material name="Material.016" specular="0.5" shininess="0.5999999940395355"
      reflectance="0.0" rgba="0.5 0.5 0.5 1.0" />
    <material name="Material.017" specular="0.5" shininess="0.5999999940395355"
      reflectance="0.0" rgba="0.5 0.5 0.5 1.0" />
    <material name="Material.018" specular="0.5" shininess="0.5999999940395355"
      reflectance="0.0" rgba="0.5 0.5 0.5 1.0" />
    <material name="Kontakt.001" specular="0.5" shininess="0.5999999940395355" reflectance="0.0"
      rgba="0.800000011920929 0.800000011920929 0.800000011920929 1.0" />
    <mesh name="Object_0.004_Metal.001" file="Object_0.004_Metal.001.msh" />
    <mesh name="Object_0.004_Wheel_Metal_Dark.001" file="Object_0.004_Wheel_Metal_Dark.001.msh" />
    <mesh name="Object_0.004_Hub_Plastic.001" file="Object_0.004_Hub_Plastic.001.msh" />
    <mesh name="Object_0.004_Rollers.001" file="Object_0.004_Rollers.001.msh" />
    <mesh name="Object_0.004_Wheel_Metal.001" file="Object_0.004_Wheel_Metal.001.msh" />
    <material name="Metal.001" specular="0.5" shininess="0.5999999940395355" reflectance="0.0"
      rgba="0.5 0.5 0.5 1.0" />
    <material name="Wheel_Metal_Dark.001" specular="0.5" shininess="0.5999999940395355"
      reflectance="0.0"
      rgba="0.044895049184560776 0.044895049184560776 0.044895049184560776 1.0" />
    <material name="Hub_Plastic.001" specular="0.5" shininess="0.5999999940395355"
      reflectance="0.0" rgba="0.4222089946269989 0.47369301319122314 0.5324400067329407 1.0" />
    <material name="Rollers.001" specular="0.5" shininess="0.5999999940395355" reflectance="0.0"
      rgba="0.6146150231361389 0.004041839856654406 0.0 1.0" />
    <material name="Wheel_Metal.001" specular="0.5" shininess="0.5999999940395355"
      reflectance="0.0" rgba="0.2699350118637085 0.2699350118637085 0.2699350118637085 1.0" />
    <mesh name="Cylinder.024_Material.019" file="Cylinder.024_Material.019.msh" />
    <material name="Material.019" specular="0.5" shininess="0.5999999940395355"
      reflectance="0.0" rgba="0.800000011920929 0.800000011920929 0.800000011920929 1.0" />
    <mesh name="Cube.010_Material.018" file="Cube.010_Material.018.msh" />
    <mesh name="Cube.010_Material.017" file="Cube.010_Material.017.msh" />
    <mesh name="Cube.090_Schwarz_plastik.002" file="Cube.090_Schwarz_plastik.002.msh" />
    <material name="Schwarz_plastik.002" specular="0.5" shininess="0.5999999940395355"
      reflectance="0.0" rgba="0.2 0.2 0.2 1.0" />
    <mesh name="Cylinder.025_LED_Grün.001" file="Cylinder.025_LED_Grün.001.msh" />
    <material name="LED_Grün.001" specular="0.5" shininess="0.5999999940395355"
      reflectance="0.0" rgba="0.2 0.2 0.2 1.0" />
    <mesh name="Cylinder.026_LED_Grün.001" file="Cylinder.026_LED_Grün.001.msh" />
    <mesh name="Cylinder.027_LED_Grün.001" file="Cylinder.027_LED_Grün.001.msh" />
    <mesh name="Circle.006_metal.Black.001" file="Circle.006_metal.Black.001.msh" />
    <material name="metal.Black.001" specular="0.5" shininess="0.5999999940395355"
      reflectance="0.0" rgba="0.2 0.2 0.2 1.0" />
    <mesh name="Cube.091_metalAxis.001" file="Cube.091_metalAxis.001.msh" />
    <material name="metalAxis.001" specular="0.5" shininess="0.5999999940395355"
      reflectance="0.0" rgba="0.800000011920929 0.800000011920929 0.800000011920929 1.0" />
    <mesh name="Cylinder.028_metalAxis.001" file="Cylinder.028_metalAxis.001.msh" />
    <mesh name="Circle.111_metal.Black.001" file="Circle.111_metal.Black.001.msh" />
    <mesh name="Cube.092_metalAxis.001" file="Cube.092_metalAxis.001.msh" />
    <mesh name="Circle.112_metal.Black.001" file="Circle.112_metal.Black.001.msh" />
    <mesh name="Cube.093_metalAxis.001" file="Cube.093_metalAxis.001.msh" />
    <mesh name="Plane.070_metal.001" file="Plane.070_metal.001.msh" />
    <material name="metal.001" specular="0.5" shininess="0.5999999940395355" reflectance="0.0"
      rgba="0.5 0.5 0.5 1.0" />
    <mesh name="Plane.071_Gummi.001" file="Plane.071_Gummi.001.msh" />
    <mesh name="Plane.071_metal.001" file="Plane.071_metal.001.msh" />
    <material name="Gummi.001" specular="0.5" shininess="0.5999999940395355" reflectance="0.0"
      rgba="0.2 0.2 0.2 1.0" />
    <mesh name="Circle.113_metal.001" file="Circle.113_metal.001.msh" />
    <mesh name="Circle.113_Kontakt.001" file="Circle.113_Kontakt.001.msh" />
    <mesh name="Circle.113_weiss.001" file="Circle.113_weiss.001.msh" />
    <material name="weiss.001" specular="0.5" shininess="0.5999999940395355" reflectance="0.0"
      rgba="0.800000011920929 0.800000011920929 0.800000011920929 1.0" />
    <mesh name="Circle.114_metal.001" file="Circle.114_metal.001.msh" />
    <mesh name="Circle.114_Kontakt.001" file="Circle.114_Kontakt.001.msh" />
    <mesh name="Circle.114_weiss.001" file="Circle.114_weiss.001.msh" />
    <mesh name="Plane.072_weiss.001" file="Plane.072_weiss.001.msh" />
    <mesh name="Plane.073_weiss.001" file="Plane.073_weiss.001.msh" />
    <mesh name="Unten_pcbV1000-A.003_Schwarz_plastik.002"
      file="Unten_pcbV1000-A.003_Schwarz_plastik.002.msh" />
    <mesh name="Unten_pcbV1000-A.003_metal.001" file="Unten_pcbV1000-A.003_metal.001.msh" />
    <mesh name="Unten_pcbV1000-A.003_Gold.001" file="Unten_pcbV1000-A.003_Gold.001.msh" />
    <mesh name="Unten_pcbV1000-A.003_Blau_plastik.USB.001"
      file="Unten_pcbV1000-A.003_Blau_plastik.USB.001.msh" />
    <material name="Gold.001" specular="0.5" shininess="0.5999999940395355" reflectance="0.0"
      rgba="0.800000011920929 0.800000011920929 0.800000011920929 1.0" />
    <material name="Blau_plastik.USB.001" specular="0.5" shininess="0.5999999940395355"
      reflectance="0.0" rgba="0.800000011920929 0.800000011920929 0.800000011920929 1.0" />
    <material name="LED_Rot.001" specular="0.5" shininess="0.5999999940395355" reflectance="0.0"
      rgba="0.800000011920929 0.800000011920929 0.800000011920929 1.0" />
    <mesh name="Circle.115_metal.001" file="Circle.115_metal.001.msh" />
    <mesh name="Bolt.002_metal.001" file="Bolt.002_metal.001.msh" />
    <mesh name="Circle.116_metal.Black.001" file="Circle.116_metal.Black.001.msh" />
    <mesh name="Circle.117_metal.Black.001" file="Circle.117_metal.Black.001.msh" />
    <mesh name="Cube.094_metalAxis.001" file="Cube.094_metalAxis.001.msh" />
    <mesh name="Cube.096_metalAxis.001" file="Cube.096_metalAxis.001.msh" />
    <mesh name="Circle.118_metalAxis.001" file="Circle.118_metalAxis.001.msh" />
    <mesh name="Circle.119_metalAxis.001" file="Circle.119_metalAxis.001.msh" />
    <mesh name="Circle.120_metalAxis.001" file="Circle.120_metalAxis.001.msh" />
    <mesh name="Circle.121_metalAxis.001" file="Circle.121_metalAxis.001.msh" />
    <mesh name="Circle.122_metalAxis.001" file="Circle.122_metalAxis.001.msh" />
    <mesh name="Circle.123_metalAxis.001" file="Circle.123_metalAxis.001.msh" />
    <mesh name="Circle.124_metalAxis.001" file="Circle.124_metalAxis.001.msh" />
    <mesh name="Circle.125_metal.Black.001" file="Circle.125_metal.Black.001.msh" />
    <mesh name="Circle.126_metal.Black.001" file="Circle.126_metal.Black.001.msh" />
    <mesh name="Circle.127_metal.Black.001" file="Circle.127_metal.Black.001.msh" />
    <mesh name="Circle.128_metalAxis.001" file="Circle.128_metalAxis.001.msh" />
    <mesh name="Circle.129_metal.Black.001" file="Circle.129_metal.Black.001.msh" />
    <mesh name="Circle.130_metal.Black.001" file="Circle.130_metal.Black.001.msh" />
    <mesh name="Circle.131_metal.Black.001" file="Circle.131_metal.Black.001.msh" />
    <mesh name="Plane.074_metal.Black.001" file="Plane.074_metal.Black.001.msh" />
    <mesh name="Plane.074_Gummi.001" file="Plane.074_Gummi.001.msh" />
    <mesh name="Plane.074_metal.001" file="Plane.074_metal.001.msh" />
    <mesh name="Cube.097_metal.Black.001" file="Cube.097_metal.Black.001.msh" />
    <mesh name="Cube.097_metal.001" file="Cube.097_metal.001.msh" />
    <mesh name="Cube.097_Gummi.001" file="Cube.097_Gummi.001.msh" />
    <mesh name="Cube.098_metal.Black.001" file="Cube.098_metal.Black.001.msh" />
    <mesh name="Cube.098_metal.001" file="Cube.098_metal.001.msh" />
    <mesh name="Cube.098_Gummi.001" file="Cube.098_Gummi.001.msh" />
    <mesh name="Cube.099_metalAxis.001" file="Cube.099_metalAxis.001.msh" />
    <mesh name="Cube.100_metalAxis.001" file="Cube.100_metalAxis.001.msh" />
    <mesh name="Circle.132_metalAxis.001" file="Circle.132_metalAxis.001.msh" />
    <mesh name="Circle.133_metalAxis.001" file="Circle.133_metalAxis.001.msh" />
    <mesh name="Circle.134_metalAxis.001" file="Circle.134_metalAxis.001.msh" />
    <mesh name="Circle.135_metalAxis.001" file="Circle.135_metalAxis.001.msh" />
    <mesh name="Circle.136_metalAxis.001" file="Circle.136_metalAxis.001.msh" />
    <mesh name="Circle.137_metalAxis.001" file="Circle.137_metalAxis.001.msh" />
    <mesh name="Circle.138_metal.Black.001" file="Circle.138_metal.Black.001.msh" />
    <mesh name="Circle.139_metal.Black.001" file="Circle.139_metal.Black.001.msh" />
    <mesh name="Circle.140_metal.Black.001" file="Circle.140_metal.Black.001.msh" />
    <mesh name="Circle.141_metalAxis.001" file="Circle.141_metalAxis.001.msh" />
    <mesh name="Circle.142_metal.Black.001" file="Circle.142_metal.Black.001.msh" />
    <mesh name="Circle.143_metal.Black.001" file="Circle.143_metal.Black.001.msh" />
    <mesh name="Circle.144_metal.Black.001" file="Circle.144_metal.Black.001.msh" />
    <mesh name="Plane.075_metal.Black.001" file="Plane.075_metal.Black.001.msh" />
    <mesh name="Plane.075_Gummi.001" file="Plane.075_Gummi.001.msh" />
    <mesh name="Plane.075_metal.001" file="Plane.075_metal.001.msh" />
    <mesh name="Cube.101_metal.Black.001" file="Cube.101_metal.Black.001.msh" />
    <mesh name="Cube.101_metal.001" file="Cube.101_metal.001.msh" />
    <mesh name="Cube.101_Gummi.001" file="Cube.101_Gummi.001.msh" />
    <mesh name="Cube.102_metal.Black.001" file="Cube.102_metal.Black.001.msh" />
    <mesh name="Cube.102_metal.001" file="Cube.102_metal.001.msh" />
    <mesh name="Cube.102_Gummi.001" file="Cube.102_Gummi.001.msh" />
    <mesh name="Circle.145_metal.Black.001" file="Circle.145_metal.Black.001.msh" />
    <mesh name="Circle.146_metal.Black.001" file="Circle.146_metal.Black.001.msh" />
    <mesh name="Circle.147_metalAxis.001" file="Circle.147_metalAxis.001.msh" />
    <mesh name="Circle.148_metalAxis.001" file="Circle.148_metalAxis.001.msh" />
    <mesh name="Circle.149_metalAxis.001" file="Circle.149_metalAxis.001.msh" />
    <mesh name="Cube.103_metalAxis.001" file="Cube.103_metalAxis.001.msh" />
    <mesh name="Circle.150_metalAxis.001" file="Circle.150_metalAxis.001.msh" />
    <mesh name="Circle.151_metalAxis.001" file="Circle.151_metalAxis.001.msh" />
    <mesh name="Circle.152_metalAxis.001" file="Circle.152_metalAxis.001.msh" />
    <mesh name="Circle.153_metalAxis.001" file="Circle.153_metalAxis.001.msh" />
    <mesh name="Cube.104_metalAxis.001" file="Cube.104_metalAxis.001.msh" />
    <mesh name="Circle.154_metal.Black.001" file="Circle.154_metal.Black.001.msh" />
    <mesh name="Circle.155_metal.Black.001" file="Circle.155_metal.Black.001.msh" />
    <mesh name="Circle.156_metal.Black.001" file="Circle.156_metal.Black.001.msh" />
    <mesh name="Circle.157_metalAxis.001" file="Circle.157_metalAxis.001.msh" />
    <mesh name="Circle.158_metal.Black.001" file="Circle.158_metal.Black.001.msh" />
    <mesh name="Circle.159_metal.Black.001" file="Circle.159_metal.Black.001.msh" />
    <mesh name="Circle.160_metal.Black.001" file="Circle.160_metal.Black.001.msh" />
    <mesh name="Plane.076_metal.Black.001" file="Plane.076_metal.Black.001.msh" />
    <mesh name="Plane.076_Gummi.001" file="Plane.076_Gummi.001.msh" />
    <mesh name="Plane.076_metal.001" file="Plane.076_metal.001.msh" />
    <mesh name="Cube.105_metal.Black.001" file="Cube.105_metal.Black.001.msh" />
    <mesh name="Cube.105_metal.001" file="Cube.105_metal.001.msh" />
    <mesh name="Cube.105_Gummi.001" file="Cube.105_Gummi.001.msh" />
    <mesh name="Cube.106_metal.Black.001" file="Cube.106_metal.Black.001.msh" />
    <mesh name="Cube.106_metal.001" file="Cube.106_metal.001.msh" />
    <mesh name="Cube.106_Gummi.001" file="Cube.106_Gummi.001.msh" />
    <mesh name="Circle.161_metal.Black.001" file="Circle.161_metal.Black.001.msh" />
    <mesh name="Circle.162_metal.Black.001" file="Circle.162_metal.Black.001.msh" />
    <mesh name="Circle.163_metalAxis.001" file="Circle.163_metalAxis.001.msh" />
    <mesh name="Circle.164_metal.001" file="Circle.164_metal.001.msh" />
    <mesh name="Cylinder.029_Material.016" file="Cylinder.029_Material.016.msh" />
    <mesh name="Cylinder.029_Material.017" file="Cylinder.029_Material.017.msh" />
    <mesh name="Cylinder.029_Kontakt.001" file="Cylinder.029_Kontakt.001.msh" />
    <mesh name="Circle.165_Material.016" file="Circle.165_Material.016.msh" />
    <mesh name="Circle.165_Material.020" file="Circle.165_Material.020.msh" />
    <material name="Material.020" specular="0.5" shininess="0.5999999940395355"
      reflectance="0.0" rgba="0.800000011920929 0.800000011920929 0.800000011920929 1.0" />
    <mesh name="Plane.077_metal.001" file="Plane.077_metal.001.msh" />
    <mesh name="Cylinder.030_Material.017" file="Cylinder.030_Material.017.msh" />
    <mesh name="Object_0.005_Metal.001" file="Object_0.005_Metal.001.msh" />
    <mesh name="Object_0.005_Wheel_Metal_Dark.001" file="Object_0.005_Wheel_Metal_Dark.001.msh" />
    <mesh name="Object_0.005_Hub_Plastic.001" file="Object_0.005_Hub_Plastic.001.msh" />
    <mesh name="Object_0.005_Rollers.001" file="Object_0.005_Rollers.001.msh" />
    <mesh name="Object_0.005_Wheel_Metal.001" file="Object_0.005_Wheel_Metal.001.msh" />
    <mesh name="Object_0.005_Material.016" file="Object_0.005_Material.016.msh" />
    <mesh name="Object_0.005_Material.017" file="Object_0.005_Material.017.msh" />
    <mesh name="Object_0.005_Kontakt.001" file="Object_0.005_Kontakt.001.msh" />
    <mesh name="Cylinder.031_Material.016" file="Cylinder.031_Material.016.msh" />
    <mesh name="Cylinder.031_Material.017" file="Cylinder.031_Material.017.msh" />
    <mesh name="Cylinder.032_Material.016" file="Cylinder.032_Material.016.msh" />
    <mesh name="Cylinder.032_Material.017" file="Cylinder.032_Material.017.msh" />
    <mesh name="Cylinder.033_Material.018" file="Cylinder.033_Material.018.msh" />
    <mesh name="Cylinder.034_Material.018" file="Cylinder.034_Material.018.msh" />
    <mesh name="Circle.166_Material.016" file="Circle.166_Material.016.msh" />
    <mesh name="Circle.166_Material.020" file="Circle.166_Material.020.msh" />
    <mesh name="Cylinder.035_Material.016" file="Cylinder.035_Material.016.msh" />
    <mesh name="Cylinder.035_Material.017" file="Cylinder.035_Material.017.msh" />
    <mesh name="Cylinder.035_Kontakt.001" file="Cylinder.035_Kontakt.001.msh" />
    <mesh name="Cylinder.036_Material.017" file="Cylinder.036_Material.017.msh" />
    <mesh name="Object_0.006_Metal.001" file="Object_0.006_Metal.001.msh" />
    <mesh name="Object_0.006_Wheel_Metal_Dark.001" file="Object_0.006_Wheel_Metal_Dark.001.msh" />
    <mesh name="Object_0.006_Hub_Plastic.001" file="Object_0.006_Hub_Plastic.001.msh" />
    <mesh name="Object_0.006_Rollers.001" file="Object_0.006_Rollers.001.msh" />
    <mesh name="Object_0.006_Wheel_Metal.001" file="Object_0.006_Wheel_Metal.001.msh" />
    <mesh name="Object_0.006_Material.016" file="Object_0.006_Material.016.msh" />
    <mesh name="Object_0.006_Material.017" file="Object_0.006_Material.017.msh" />
    <mesh name="Object_0.006_Kontakt.001" file="Object_0.006_Kontakt.001.msh" />
    <mesh name="Circle.167_Material.020" file="Circle.167_Material.020.msh" />
    <mesh name="Circle.168_Material.020" file="Circle.168_Material.020.msh" />
    <material name="black" rgba="0.2 0.2 0.2 1" />

  </asset>

  <actuator>
    <velocity class="wheel" name="l_wheel" joint="l_wheel" />
    <velocity class="wheel" name="r_wheel" joint="r_wheel" />
    <velocity class="wheel" name="middle_wheel" joint="middle_wheel" />

    <!-- left leg -->
    <position name="l_leg_hinge1" joint="l_leg_hinge1" kp="100" kv="25" />
    <position name="l_leg_hinge2" joint="l_leg_hinge2" kp="100" kv="25" />
    <position name="l_leg_slide" joint="l_leg_slide" kp="100" kv="25" ctrlrange="-1 0.1" />

    <!-- right leg -->
    <position name="r_leg_hinge1" joint="r_leg_hinge1" kp="100" kv="25" />
    <position name="r_leg_hinge2" joint="r_leg_hinge2" kp="100" kv="25" />
    <position name="r_leg_slide" joint="r_leg_slide" kp="100" kv="25" ctrlrange="-1 0.1" />

    <!-- arm -->
    <position name="finger_1" joint="finger_1" kp="5" kv="1" ctrlrange="-1 0.7" />
    <position name="finger_2" joint="finger_2" kp="5" kv="1" ctrlrange="-1 0.7" />
    <position name="finger_3" joint="finger_3" kp="5" kv="1" ctrlrange="-1 0.7" />
    <position name="wrist_1" joint="wrist_1" kp="5" kv="1" ctrlrange="-1.5 1.5" />
    <position name="wrist_2" joint="wrist_2" kp="5" kv="1" ctrlrange="-2 2" />
    <position name="arm_column_slide_1" joint="arm_column_slide_1" kp="100" kv="20"
      ctrlrange="-1.5 1.5" />
    <position name="arm_column_slide_2" joint="arm_column_slide_2" kp="100" kv="20"
      ctrlrange="-1.5 1.5" />
    <position name="arm_slide" joint="arm_slide" kp="100" kv="20" ctrlrange="-0.5 0.8" />
  </actuator>
  <compiler assetdir="exported" boundmass="1e-3" boundinertia="1e-9" />
</mujoco>